<?xml version="1.0"?>
<robot name="robot_arm">

  <!-- Materials -->
  <material name="yellow">
    <color rgba="1.0 1.0 0.0 1"/>
  </material>
  <material name="orange">
    <color rgba="1.0 0.5 0.0 1"/>
  </material>

  <!-- Base -->
  <link name="base_link">
    <visual>
      <geometry>
        <box size="0.4 0.4 0.1"/>
      </geometry>
      <origin xyz="0 0 0.05" rpy="0 0 0"/>
      <material name="yellow"/>
    </visual>
    <collision>
      <geometry>
        <box size="0.4 0.4 0.1"/>
      </geometry>
      <origin xyz="0 0 0.05" rpy="0 0 0"/>
    </collision>
  </link>

  <!-- Shoulder -->
  <link name="shoulder_link">
    <visual>
      <geometry>
        <cylinder length="0.5" radius="0.1"/>
      </geometry>
      <origin xyz="0 0 0.25" rpy="0 0 0"/>
      <material name="orange"/>
    </visual>
    <collision>
      <geometry>
        <box size="0.2 0.2 0.5"/>
      </geometry>
      <origin xyz="0 0 0.25" rpy="0 0 0"/>
    </collision>
  </link>

  <!-- Arm -->
  <link name="arm_link">
    <visual>
      <geometry>
        <cylinder length="0.6" radius="0.05"/>
      </geometry>
      <origin xyz="0 0 0.3" rpy="0 0 0"/>
      <material name="yellow"/>
    </visual>
    <collision>
      <geometry>
        <box size="0.1 0.1 0.6"/>
      </geometry>
      <origin xyz="0 0 0.3" rpy="0 0 0"/>
    </collision>
  </link>

  <!-- Elbow -->
  <link name="elbow_link">
    <visual>
      <geometry>
        <cylinder length="0.1" radius="0.05"/>
      </geometry>
      <origin xyz="0 0 0.05" rpy="0 0 0"/>
      <material name="orange"/>
    </visual>
    <collision>
      <geometry>
        <box size="0.1 0.1 0.1"/>
      </geometry>
      <origin xyz="0 0 0.05" rpy="0 0 0"/>
    </collision>
  </link>

  <!-- Forearm -->
  <link name="forearm_link">
    <visual>
      <geometry>
        <cylinder length="0.5" radius="0.05"/>
      </geometry>
      <origin xyz="0 0 0.25" rpy="0 0 0"/>
      <material name="yellow"/>
    </visual>
    <collision>
      <geometry>
        <box size="0.1 0.1 0.5"/>
      </geometry>
      <origin xyz="0 0 0.25" rpy="0 0 0"/>
    </collision>
  </link>

  <!-- Wrist -->
  <link name="wrist_link">
    <visual>
      <geometry>
        <box size="0.1 0.1 0.05"/>
      </geometry>
      <origin xyz="0 0 0.025" rpy="0 0 0"/>
      <material name="orange"/>
    </visual>
    <collision>
      <geometry>
        <box size="0.1 0.1 0.05"/>
      </geometry>
      <origin xyz="0 0 0.025" rpy="0 0 0"/>
    </collision>
  </link>

  <!-- Hand -->
  <link name="hand_link">
    <visual>
      <geometry>
        <box size="0.1 0.1 0.02"/>
      </geometry>
      <origin xyz="0 0 0.01" rpy="0 0 0"/>
      <material name="yellow"/>
    </visual>
    <collision>
      <geometry>
        <box size="0.1 0.1 0.02"/>
      </geometry>
      <origin xyz="0 0 0.01" rpy="0 0 0"/>
    </collision>
  </link>

  <!-- Gripper base -->
  <link name="gripper_base">
    <visual>
      <geometry>
        <box size="0.05 0.05 0.02"/>
      </geometry>
      <origin xyz="0 0 0.01" rpy="0 0 0"/>
      <material name="orange"/>
    </visual>
  </link>

  <!-- Left finger -->
  <link name="left_finger">
    <visual>
      <geometry>
        <box size="0.02 0.1 0.02"/>
      </geometry>
      <origin xyz="0.03 0 0.01" rpy="0 0 0"/>
      <material name="yellow"/>
    </visual>
  </link>

  <!-- Right finger -->
  <link name="right_finger">
    <visual>
      <geometry>
        <box size="0.02 0.1 0.02"/>
      </geometry>
      <origin xyz="-0.03 0 0.01" rpy="0 0 0"/>
      <material name="yellow"/>
    </visual>
  </link>

  <!-- Joints -->
  <joint name="joint1" type="revolute">
    <parent link="base_link"/>
    <child link="shoulder_link"/>
    <origin xyz="0 0 0.1" rpy="0 0 0"/>
    <axis xyz="0 0 1"/>
    <limit effort="1000.0" velocity="1.0" lower="-1.5" upper="1.5"/>
  </joint>

  <joint name="joint2" type="revolute">
    <parent link="shoulder_link"/>
    <child link="arm_link"/>
    <origin xyz="0 0 0.5" rpy="0 0 0"/>
    <axis xyz="0 1 0"/>
    <limit effort="1000.0" velocity="1.0" lower="-1.1" upper="1.1"/>
  </joint>

  <joint name="joint3" type="revolute">
    <parent link="arm_link"/>
    <child link="elbow_link"/>
    <origin xyz="0 0 0.6" rpy="0 0 0"/>
    <axis xyz="0 1 0"/>
    <limit effort="1000.0" velocity="1.0" lower="0" upper="2.3"/>
  </joint>

  <joint name="joint4" type="revolute">
    <parent link="elbow_link"/>
    <child link="forearm_link"/>
    <origin xyz="0 0 0.1" rpy="0 0 0"/>
    <axis xyz="0 0 1"/>
    <limit effort="1000.0" velocity="1.0" lower="-1.5" upper="1.5"/>
  </joint>

  <joint name="joint5" type="revolute">
    <parent link="forearm_link"/>
    <child link="wrist_link"/>
    <origin xyz="0 0 0.5" rpy="0 0 0"/>
    <axis xyz="0 1 0"/>
    <limit effort="1000.0" velocity="1.0" lower="-1.2" upper="1.2"/>
  </joint>

  <joint name="joint6" type="continuous">
    <parent link="wrist_link"/>
    <child link="hand_link"/>
    <origin xyz="0 0 0.05" rpy="0 0 0"/>
    <axis xyz="0 0 1"/>
  </joint>

  <!-- Attach gripper base -->
  <joint name="hand_gripper_joint" type="fixed">
    <parent link="hand_link"/>
    <child link="gripper_base"/>
    <origin xyz="0 0 0.02" rpy="0 0 0"/>
  </joint>

  
    <!-- Finger joints -->
  <joint name="left_finger_joint" type="prismatic">
    <parent link="gripper_base"/>
    <child link="left_finger"/>
    <origin xyz="0.03 0 0" rpy="0 0 0"/>
    <axis xyz="1 0 0"/>
    <limit effort="10.0" velocity="0.1" lower="0.0" upper="0.02"/>
  </joint>

  <joint name="right_finger_joint" type="prismatic">
    <parent link="gripper_base"/>
    <child link="right_finger"/>
    <origin xyz="-0.03 0 0" rpy="0 0 0"/>
    <axis xyz="-1 0 0"/>
    <limit effort="10.0" velocity="0.1" lower="0.0" upper="0.02"/>
  </joint>

</robot>
